Workbook
Name _Hlk104232410: CONTRATOS!$M$603
Name _Hlk112011606: CONTRATOS!$L$717
Name _Hlk113616823: CONTRATOS!$I$674
Name _Hlk118841670: PROCESOS!$E$844
Name _Hlk161317399: PROCESOS!$E$815
Name _Hlk91169232: CONTRATOS!$L$704
Name _Hlk94027716: PROCESOS!$E$412
Name _Hlk99553524: CONTRATOS!$L$589
Name AREA_ORDENADORA: Listas!$A$2:$A$14
Name AREA_SOLICITANTE: Listas!$E$2:$E$19
Name OFICINA_ASESORA_DE_COMUNICACIONES: Listas!$S$2:$S$3
Name OFICINA_ASESORA_DE_PLANEACIÓN: Listas!$M$2:$M$3
Name OFICINA_ASESORA_JURÍDICA: Listas!$N$2:$N$3
Name OFICINA_COMERCIAL_Y_DE_MERCADEO: Listas!$R$2:$R$5
Name OFICINA_DE_CONTROL_INTERNO: Listas!$O$2:$O$3
Name OFICINA_DE_RELACIONES_INTERNACIONALES: Listas!$P$2:$P$3
Name OFICINA_DE_RIESGOS: Listas!$Q$2:$Q$5
Name PRESIDENCIA: Listas!$G$2
Name SECRETARÍA_GENERAL: Listas!$H$2:$H$11
Name TERRITORIAL_CENTRO: Listas!$T$2
Name TERRITORIAL_NOROCCIDENTE: Listas!$U$2
Name TERRITORIAL_NORTE: Listas!$W$2
Name TERRITORIAL_ORIENTE: Listas!$X$2
Name TERRITORIAL_SUROCCIDENTE: Listas!$V$2
Name VICEPRESIDENCIA_DE_CRÉDITO_Y_COBRANZA: Listas!$I$2:$I$4
Name VICEPRESIDENCIA_DE_FONDOS_EN_ADMINISTRACIÓN: Listas!$J$2:$J$8
Name VICEPRESIDENCIA_DE_OPERACIONES_Y_TECNOLOGÍA: Listas!$K$2:$K$19
Name VICEPRESIDENCIA_FINANCIERA: Listas!$L$2:$L$11

Sheet MENU
B2: MENU
B4: BASE CONTRATOS
B6: BASE PROCESOS
B8: BASE OTROSÍ CONVENIOS
B10: BASE OTROSÍ CONTRATOS
B12: BASE LIQUIDACIONES

Sheet Hoja1

Sheet Hoja2

Sheet Hoja3

Sheet CONTRATOS
A1: i | B1: No. Cto | C1: TIPO DE CONTRATO | D1: NÚMERO DEL PROCESO DE SELECCIÓN TAL CUAL APARECE EN LA MINUTA Y COMO FUE PUBLICADO EN EL SECOP | E1: CLASE DE CONTRATO | F1: CONTRATISTA: NATURALEZA | G1: CONTRATISTA: TIPO IDENTIFICACIÓN | H1: CONTRATISTA: NÚMERO DE IDENTIFICACIÓN | I1: CONTRATISTA : NOMBRE COMPLETO O RAZON SOCIAL | J1: CONTRATISTA: NOMBRE DEL REPRESENTANTE LEGAL | K1: CONTRATISTA: REPRESENTANTE LEGAL - NÚMERO DE CÉDULA | L1: OBJETO DEL CONTRATO Y/O CONVENIO | M1: LUGAR DE EJECUCIÓN DEL CONTRATO (MUNICIPIO) | N1: FECHA DE SUSCRIPCIÓN | O1: FECHA DE INICIO | P1: FECHA DE TERMINACIÓN INICIAL | Q1: PLAZO INICIAL DEL CONTRATO | R1: AFECTACIÓN DEL RECURSO | S1: Nº CDP: Disp.presupuestal | T1: PROYECTO | U1: CDP: Valor | V1: RP - Rubro | W1: VALOR INICIAL CONTRATO | X1: FORMA DE PAGO: HONORARIOS MENSUALES PACTADOS PARA PRESTACIÓN DE SERVICIO ASISTENCIAL O PROFESIONAL | Y1: VALOR CONVENIO | Z1: No PÓLIZA | AA1: ÁREA ORDENADORA DEL GASTO | AB1: ORDENADOR: NOMBRE COMPLETO | AC1: ORDENADOR: NÚMERO DE CÉDULA | AD1: ÁREA SOLICITANTE | AE1: SUPERVISOR: CARGO DEL SUPERVISOR | AF1: SUPERVISOR: NOMBRE COMPLETO | AG1: SUPERVISOR: NÚMERO DE CÉDULA | AH1: MODALIDAD DE SELECCIÓN | AI1: OBLIGACIONES ESPECIFICAS | AJ1: VINCULACIÓN SIGEP | AK1: PUBLICACIÓN PROACTIVA DECLARACIÓN DE BIENES Y RENTAS Y REGISTRO DE CONFLICTOS DE INTERÉS | AL1: DECLARACIÓN DE RENTA | AM1: CURSO DE TRANSPARENCIA | AN1: FECHA DE NACIMIENTO (PRESTACIÓN DE SERVICIOS PERSONA NATURAL) | AO1: EDAD | AP1: GRUPO TRAMITADOR | AQ1: ABOGADO | AR1: CESIÓN 1: FECHA DE SUSCRIPCIÓN | AS1: CESIÓN 1: NOMBRE COMPLETO | AT1: CESIÓN 1: No. IDENTIFICACIÓN | AU1: CESIÓN 1: OBJETO | AV1: CESIÓN 1: VALOR CESIONADO | AW1: CESIÓN 2: FECHA DE SUSCRIPCIÓN | AX1: CESIÓN 2: NOMBRE COMPLETO | AY1: CESIÓN 2: No. IDENTIFICACIÓN | AZ1: CESIÓN 2: OBJETO | BA1: CESIÓN 2: VALOR CESIONADO | BB1: PRORROGA 1: FECHA SUSCRIPCION | BC1: PRORROGA 1: PLAZO | BD1: PRORROGA 2: FECHA | BE1: PRORROGA 2: PLAZO | BF1: TOTAL DÍAS PRORROGADOS | BG1: DISMINUCIÓN DE NÚMERO DE DIASTERMINACIÓN ANTICIPADA | BH1: FECHA TERMINACIÓN ANTICIPADA | BI1: PLAZO TOTAL DEL CONTRATO | BJ1: FECHA DE TERMINACIÓN FINAL | BK1: MODIFICACIÓN 1: FECHA DE SUSCRIPCIÓN | BL1: MODIFICIACIÓN 1: OBJETO | BM1: MODIFICACIÓN 2: FECHA DE SUSCRIPCIÓN | BN1: MODIFICIACIÓN 2: OBJETO | BO1: MODIFICACIÓN 3: FECHA DE SUSCRIPCIÓN | BP1: MODIFICIACIÓN 3: OBJETO | BQ1: ADICIÓN 1: FECHA DE SUSCRIPCIÓN | BR1: ADICIÓN 1: VALOR | BS1: CDP ADICIÓN 1 | BT1: ADICIÓN 1: OBJETO | BU1: ADICIÓN 2: FECHA DE SUSCRIPCIÓN | BV1: ADICIÓN 2: VALOR | BW1: CDP ADICIÓN 2 | BX1: ADICIÓN 2: OBJETO | BY1: ADICIÓN 3: FECHA DE SUSCRIPCIÓN | BZ1: ADICIÓN 3: VALOR | CA1: CDP ADICIÓN 3 | CB1: ADICIÓN 3: OBJETO | CC1: ADICIÓN: VALOR TOTAL | CD1: DISMINUCION: VALOR | CE1: VALOR FINAL DEL CONTRATO DESPUES DE MODIFICACIONES | CF1: VALOR EJECUTADO (DILIGENCIA FINANCIERA) | CG1: VALOR PAGADO PROGRAMADO | CH1: PORCENTAJE DE AVANCE FÍSICO PROGRAMADO | CI1: PORCENTAJE DE AVANCE FÍSICO REAL | CJ1: PORCENTAJE AVANCE PRESUPUESTAL PROGRAMADO | CK1: PORCENTAJE AVANCE PRESUPUESTAL REAL | CL1: FECHA DE LIQUIDACIÓN DEL CONTRATO | CM1: ESTADO | CN1: OBSERVACIONES | CO1: NUMERO DE RADICADO | CP1: GENERO | CQ1: NUMERO DE REGISTRO PRESUPUESTAL | CR1: NUMERO DE REGISTRO PRESUPUESTAL ADICION / CESION
A2: 13.38 | B2: 2024-0001 | C2: CTO | D2: CD-001-2024 | E2: 9 PRESTACIÓN DE SERVICIOS | F2: 1 PERSONA NATURAL | G2: 3 CÉDULA DE CIUDADANÍA | H2: 52935588 | I2: GIOHANA CATARINE GONZALES TURIZO | L2: 13.38 PRESTACIÓN DE SERVICIOS PROFESIONALES COMO ABOGADO PARA APOYAR EL DESARROLLO Y SEGUIMIENTO DE LA ACTIVIDAD CONTRACTUAL EN EL MARCO DEL PROYECTO DE FORTALECIMIENTO ORGANIZACIONAL Y LA IMPLEMENTACIÓN DE LA POLÍTICA DE COMPRAS PÚBLICAS Y DE CONTRATACIÓN DEL ICETEX | M2: BOGOTA | N2: 45294 | O2: 45294 | P2: 45475 | Q2: =P2-O2 -> 181 | R2: 2 INVERSIÓN | S2: CDEF-24-2024 | T2: FORTALECIMIENTO ORGANIZACIONAL | U2: 105619200 | V2: IG 332901003 | W2: 105619200 | X2: 8801600 | AA2: SECRETARÍA_GENERAL | AB2: =IFERROR(VLOOKUP(AA2,Listas!$A$1:$C$14,2,FALSE),"") -> FREDY CÉSPEDES VILLA | AC2: =IFERROR(VLOOKUP(AA2,Listas!$A$1:$C$14,3,FALSE),"") -> 93363483 | AD2: SECRETARÍA_GENERAL | AE2: COORDINADOR(A) GRUPO DE CONTRATACIÓN | AF2: =IFERROR(VLOOKUP(AE2,Listas!$AD$1:$AF$66,2,FALSE),"") -> DIANA BARRERA MEDINA | AG2: =IFERROR(VLOOKUP(AE2,Listas!$AD$1:$AF$65,3,FALSE),"") -> 52964360 | AH2: 1 CONTRATACION DIRECTA | AJ2: 1 SI | AK2: 1 PUBLICADO | AL2: 1 PUBLICADO | AM2: 1 SI | AN2: 30552 | AO2: =IF(YEAR(TODAY())-YEAR(AN2)>100," ",YEAR(TODAY())-YEAR(AN2)) -> 42 | AP2: GRUPO_DE_CONTRATACIÓN | AQ2: LAURA NARANJO | BF2: =BC2+BE2 -> 0 | BI2: =BF2+Q2 -> 181 | BJ2: =IF(BH2="",P2+BF2,BH2) -> 45475 | CC2: =BR2+BV2+BZ2 -> 0 | CE2: =IF(Y2=0,(W2+CC2)-CD2,IF(Y2>0,(Y2+CC2)-CD2)) -> 105619200 | CG2: =IFERROR(IF(((CE2/BI2)*(TODAY()-N2))>CE2,CE2,((CE2/BI2)*(TODAY()-N2))),"") -> 105619200 | CH2: =IF(TODAY()>BJ2,1,+(DAYS360(O2,TODAY())/DAYS360(O2,BJ2))) -> 1 | CI2: =+IF(CL2>0,DAYS360(O2,CL2)/DAYS360(O2,BJ2),CH2) -> 1 | CJ2: =IFERROR(IF(((CG2/CE2)*100)>100,100,((CG2/CE2)*100)),"") -> 100 | CK2: =IFERROR((CF2/CE2)*100,"") -> 0 | CM2: =IF(CL2>1/1/6,"LIQUIDADO",IF(BJ2=0,"",IF(BJ2>=TODAY(),"VIGENTE",IF(BJ2<TODAY(),"TERMINADO",)))) -> TERMINADO | CP2: FEMENINO
A3: 13.25 | B3: 2024-0002 | C3: CTO | D3: CD-002-2024 | E3: 9 PRESTACIÓN DE SERVICIOS | F3: 1 PERSONA NATURAL | G3: 3 CÉDULA DE CIUDADANÍA | H3: 1031129528 | I3: AMANDA CATALINA CARREÑO BUITRAGO | L3: 13.25 PRESTACIÓN DE SERVICIOS PROFESIONALES EN DERECHO PARA BRINDAR ASESORÍA JURÍDICA EN LAS DIFERENTES ETAPAS DE LA ACTIVIDAD CONTRACTUAL DE ACUERDO CON LAS POLÍTICAS DE CELEBRACIÓN Y EJECUCIÓN DE CONTRATOS EN EL MARCO DEL "PROYECTO DE FORTALECIMIENTO ORGANIZACIONAL" DEL ICETEX. | M3: BOGOTA | N3: 45294 | O3: 45295 | P3: 45656 | Q3: =P3-O3 -> 361 | R3: 2 INVERSIÓN | S3: CDEF-117-2024 | T3: FORTALECIMIENTO ORGANIZACIONAL | U3: 136518928 | V3: IG 332901003 | W3: 136518928 | X3: 11376578 | AA3: SECRETARÍA_GENERAL | AB3: =IFERROR(VLOOKUP(AA3,Listas!$A$1:$C$14,2,FALSE),"") -> FREDY CÉSPEDES VILLA | AC3: =IFERROR(VLOOKUP(AA3,Listas!$A$1:$C$14,3,FALSE),"") -> 93363483 | AD3: SECRETARÍA_GENERAL | AE3: COORDINADOR(A) GRUPO DE CONTRATACIÓN | AF3: =IFERROR(VLOOKUP(AE3,Listas!$AD$1:$AF$66,2,FALSE),"") -> DIANA BARRERA MEDINA | AG3: =IFERROR(VLOOKUP(AE3,Listas!$AD$1:$AF$65,3,FALSE),"") -> 52964360 | AH3: 1 CONTRATACION DIRECTA | AJ3: 1 SI | AK3: 1 PUBLICADO | AL3: 1 PUBLICADO | AM3: 1 SI | AN3: 33143 | AO3: =IF(YEAR(TODAY())-YEAR(AN3)>100," ",YEAR(TODAY())-YEAR(AN3)) -> 35 | AP3: GRUPO_DE_CONTRATACIÓN | AQ3: LAURA NARANJO | BF3: =BC3+BE3 -> 0 | BI3: =BF3+Q3 -> 361 | BJ3: =IF(BH3="",P3+BF3,BH3) -> 45656 | CC3: =BR3+BV3+BZ3 -> 0 | CE3: =IF(Y3=0,(W3+CC3)-CD3,IF(Y3>0,(Y3+CC3)-CD3)) -> 136518928 | CG3: =IFERROR(IF(((CE3/BI3)*(TODAY()-N3))>CE3,CE3,((CE3/BI3)*(TODAY()-N3))),"") -> 136518928 | CH3: =IF(TODAY()>BJ3,1,+(DAYS360(O3,TODAY())/DAYS360(O3,BJ3))) -> 1 | CI3: =+IF(CL3>0,DAYS360(O3,CL3)/DAYS360(O3,BJ3),CH3) -> 1 | CJ3: =IFERROR(IF(((CG3/CE3)*100)>100,100,((CG3/CE3)*100)),"") -> 100 | CK3: =IFERROR((CF3/CE3)*100,"") -> 0 | CM3: =IF(CL3>1/1/6,"LIQUIDADO",IF(BJ3=0,"",IF(BJ3>=TODAY(),"VIGENTE",IF(BJ3<TODAY(),"TERMINADO",)))) -> TERMINADO | CP3: FEMENINO
A4: 13.24 | B4: 2024-0003 | C4: CTO | D4: CD-003-2024 | E4: 9 PRESTACIÓN DE SERVICIOS | F4: 1 PERSONA NATURAL | G4: 3 CÉDULA DE CIUDADANÍA | H4: 1090501792 | I4: LAURA MARCELA LUQUE PINEDO | L4: 13.24 PRESTACIÓN DE SERVICIOS PROFESIONALES EN DERECHO PARA BRINDAR ASESORÍA JURÍDICA EN LAS DIFERENTES ETAPAS DE LA ACTIVIDAD CONTRACTUAL DE ACUERDO CON LAS POLÍTICAS DE CELEBRACIÓN Y EJECUCIÓN DE CONTRATOS EN EL MARCO DEL "PROYECTO DE FORTALECIMIENTO ORGANIZACIONAL" DEL ICETEX. | M4: BOGOTA | N4: 45294 | O4: 45294 | P4: 45656 | Q4: =P4-O4 -> 362 | R4: 2 INVERSIÓN | S4: CDEF-12-2024 | T4: FORTALECIMIENTO ORGANIZACIONAL | U4: 117702036 | V4: IG 332901003 | W4: 117702036 | X4: 9808503 | AA4: SECRETARÍA_GENERAL | AB4: =IFERROR(VLOOKUP(AA4,Listas!$A$1:$C$14,2,FALSE),"") -> FREDY CÉSPEDES VILLA | AC4: =IFERROR(VLOOKUP(AA4,Listas!$A$1:$C$14,3,FALSE),"") -> 93363483 | AD4: SECRETARÍA_GENERAL | AE4: COORDINADOR(A) GRUPO DE CONTRATACIÓN | AF4: =IFERROR(VLOOKUP(AE4,Listas!$AD$1:$AF$66,2,FALSE),"") -> DIANA BARRERA MEDINA | AG4: =IFERROR(VLOOKUP(AE4,Listas!$AD$1:$AF$65,3,FALSE),"") -> 52964360 | AH4: 1 CONTRATACION DIRECTA | AJ4: 1 SI | AK4: 1 PUBLICADO | AL4: 1 PUBLICADO | AM4: 1 SI | AN4: 35377 | AO4: =IF(YEAR(TODAY())-YEAR(AN4)>100," ",YEAR(TODAY())-YEAR(AN4)) -> 29 | AP4: GRUPO_DE_CONTRATACIÓN | AQ4: LAURA NARANJO | BF4: =BC4+BE4 -> 0 | BI4: =BF4+Q4 -> 362 | BJ4: =IF(BH4="",P4+BF4,BH4) -> 45656 | CC4: =BR4+BV4+BZ4 -> 0 | CE4: =IF(Y4=0,(W4+CC4)-CD4,IF(Y4>0,(Y4+CC4)-CD4)) -> 117702036 | CG4: =IFERROR(IF(((CE4/BI4)*(TODAY()-N4))>CE4,CE4,((CE4/BI4)*(TODAY()-N4))),"") -> 117702036 | CH4: =IF(TODAY()>BJ4,1,+(DAYS360(O4,TODAY())/DAYS360(O4,BJ4))) -> 1 | CI4: =+IF(CL4>0,DAYS360(O4,CL4)/DAYS360(O4,BJ4),CH4) -> 1 | CJ4: =IFERROR(IF(((CG4/CE4)*100)>100,100,((CG4/CE4)*100)),"") -> 100 | CK4: =IFERROR((CF4/CE4)*100,"") -> 0 | CM4: =IF(CL4>1/1/6,"LIQUIDADO",IF(BJ4=0,"",IF(BJ4>=TODAY(),"VIGENTE",IF(BJ4<TODAY(),"TERMINADO",)))) -> TERMINADO | CP4: FEMENINO
A5: 13.43 | B5: 2024-0004 | C5: CTO | D5: CD-004-2024 | E5: 9 PRESTACIÓN DE SERVICIOS | F5: 1 PERSONA NATURAL | G5: 3 CÉDULA DE CIUDADANÍA | H5: 1026294532 | I5: LUIS ESTEBAN REYES ARIAS | L5: 13.43 PRESTACIÓN DE SERVICIOS PROFESIONALES PARA APOYAR EL IMPULSO DE LOS PROCESOS, PROCEDIMIENTOS Y TRÁMITE EN LA GESTIÓN DE LA POLÍTICA DE COMPRAS PÚBLICAS Y DE CONTRATACIÓN EN EL MARCO DEL PROYECTO DE "FORTALECIMIENTO ORGANIZACIONAL" DEL ICETEX | M5: BOGOTA | N5: 45294 | O5: 45295 | P5: 45656 | Q5: =P5-O5 -> 361 | R5: 2 INVERSIÓN | S5: CDEF-28-2024 | T5: FORTALECIMIENTO ORGANIZACIONAL | U5: 69144665 | V5: IG 332901003 | W5: 69144665 | X5: 5762055 | AA5: SECRETARÍA_GENERAL | AB5: =IFERROR(VLOOKUP(AA5,Listas!$A$1:$C$14,2,FALSE),"") -> FREDY CÉSPEDES VILLA | AC5: =IFERROR(VLOOKUP(AA5,Listas!$A$1:$C$14,3,FALSE),"") -> 93363483 | AD5: SECRETARÍA_GENERAL | AE5: COORDINADOR(A) GRUPO DE CONTRATACIÓN | AF5: =IFERROR(VLOOKUP(AE5,Listas!$AD$1:$AF$66,2,FALSE),"") -> DIANA BARRERA MEDINA | AG5: =IFERROR(VLOOKUP(AE5,Listas!$AD$1:$AF$65,3,FALSE),"") -> 52964360 | AH5: 1 CONTRATACION DIRECTA | AJ5: 1 SI | AK5: 1 PUBLICADO | AL5: 1 PUBLICADO | AM5: 1 SI | AN5: 35135 | AO5: =IF(YEAR(TODAY())-YEAR(AN5)>100," ",YEAR(TODAY())-YEAR(AN5)) -> 29 | AP5: GRUPO_DE_CONTRATACIÓN | AQ5: LAURA NARANJO | BF5: =BC5+BE5 -> 0 | BI5: =BF5+Q5 -> 361 | BJ5: =IF(BH5="",P5+BF5,BH5) -> 45656 | CC5: =BR5+BV5+BZ5 -> 0 | CE5: =IF(Y5=0,(W5+CC5)-CD5,IF(Y5>0,(Y5+CC5)-CD5)) -> 69144665 | CG5: =IFERROR(IF(((CE5/BI5)*(TODAY()-N5))>CE5,CE5,((CE5/BI5)*(TODAY()-N5))),"") -> 69144665 | CH5: =IF(TODAY()>BJ5,1,+(DAYS360(O5,TODAY())/DAYS360(O5,BJ5))) -> 1 | CI5: =+IF(CL5>0,DAYS360(O5,CL5)/DAYS360(O5,BJ5),CH5) -> 1 | CJ5: =IFERROR(IF(((CG5/CE5)*100)>100,100,((CG5/CE5)*100)),"") -> 100 | CK5: =IFERROR((CF5/CE5)*100,"") -> 0 | CM5: =IF(CL5>1/1/6,"LIQUIDADO",IF(BJ5=0,"",IF(BJ5>=TODAY(),"VIGENTE",IF(BJ5<TODAY(),"TERMINADO",)))) -> TERMINADO | CP5: MASCULINO
A6: 13.33 | B6: 2024-0005 | C6: CTO | D6: CD-005-2024 | E6: 9 PRESTACIÓN DE SERVICIOS | F6: 1 PERSONA NATURAL | G6: 3 CÉDULA DE CIUDADANÍA | H6: 1094927338 | I6: LAURA NARANJO JARAMILLO | L6: 13.33 PRESTACIÓN DE SERVICIOS PROFESIONALES COMO ABOGADO PARA APOYAR EL DESARROLLO Y SEGUIMIENTO DE LA ACTIVIDAD CONTRACTUAL EN EL MARCO DEL PROYECTO DE FORTALECIMIENTO ORGANIZACIONAL Y LA IMPLEMENTACIÓN DE LA POLÍTICA DE COMPRAS PÚBLICAS Y DE CONTRATACIÓN DEL ICETEX | M6: BOGOTA | N6: 45294 | O6: 45294 | P6: 45656 | Q6: =P6-O6 -> 362 | R6: 2 INVERSIÓN | S6: CDEF-19-2024 | T6: FORTALECIMIENTO ORGANIZACIONAL | U6: 102790731 | V6: IG 332901003 | W6: 102790731 | X6: 8565894 | AA6: SECRETARÍA_GENERAL | AB6: =IFERROR(VLOOKUP(AA6,Listas!$A$1:$C$14,2,FALSE),"") -> FREDY CÉSPEDES VILLA | AC6: =IFERROR(VLOOKUP(AA6,Listas!$A$1:$C$14,3,FALSE),"") -> 93363483 | AD6: SECRETARÍA_GENERAL | AE6: COORDINADOR(A) GRUPO DE CONTRATACIÓN | AF6: =IFERROR(VLOOKUP(AE6,Listas!$AD$1:$AF$66,2,FALSE),"") -> DIANA BARRERA MEDINA | AG6: =IFERROR(VLOOKUP(AE6,Listas!$AD$1:$AF$65,3,FALSE),"") -> 52964360 | AH6: 1 CONTRATACION DIRECTA | AJ6: 1 SI | AK6: 1 PUBLICADO | AL6: 1 PUBLICADO | AM6: 1 SI | AN6: 33732 | AO6: =IF(YEAR(TODAY())-YEAR(AN6)>100," ",YEAR(TODAY())-YEAR(AN6)) -> 33 | AP6: GRUPO_DE_CONTRATACIÓN | AQ6: LAURA NARANJO | BF6: =BC6+BE6 -> 0 | BI6: =BF6+Q6 -> 362 | BJ6: =IF(BH6="",P6+BF6,BH6) -> 45656 | CC6: =BR6+BV6+BZ6 -> 0 | CE6: =IF(Y6=0,(W6+CC6)-CD6,IF(Y6>0,(Y6+CC6)-CD6)) -> 102790731 | CG6: =IFERROR(IF(((CE6/BI6)*(TODAY()-N6))>CE6,CE6,((CE6/BI6)*(TODAY()-N6))),"") -> 102790731 | CH6: =IF(TODAY()>BJ6,1,+(DAYS360(O6,TODAY())/DAYS360(O6,BJ6))) -> 1 | CI6: =+IF(CL6>0,DAYS360(O6,CL6)/DAYS360(O6,BJ6),CH6) -> 1 | CJ6: =IFERROR(IF(((CG6/CE6)*100)>100,100,((CG6/CE6)*100)),"") -> 100 | CK6: =IFERROR((CF6/CE6)*100,"") -> 0 | CM6: =IF(CL6>1/1/6,"LIQUIDADO",IF(BJ6=0,"",IF(BJ6>=TODAY(),"VIGENTE",IF(BJ6<TODAY(),"TERMINADO",)))) -> TERMINADO | CP6: FEMENINO
A7: 13.28 | B7: 2024-0006 | C7: CTO | D7: CD-006-2024 | E7: 9 PRESTACIÓN DE SERVICIOS | F7: 1 PERSONA NATURAL | G7: 3 CÉDULA DE CIUDADANÍA | H7: 1026288361 | I7: DAHYANNA JIMENA ANGARITA SALAZAR | L7: 13.28 PRESTACIÓN DE SERVICIOS PROFESIONALES COMO ABOGADO PARA APOYAR EL DESARROLLO Y SEGUIMIENTO DE LA ACTIVIDAD CONTRACTUAL EN EL MARCO DEL PROYECTO DE FORTALECIMIENTO ORGANIZACIONAL Y LA IMPLEMENTACIÓN DE LA POLÍTICA DE COMPRAS PÚBLICAS Y DE CONTRATACIÓN DEL ICETEX | M7: BOGOTA | N7: 45294 | O7: 45295 | P7: 45656 | Q7: =P7-O7 -> 361 | R7: 2 INVERSIÓN | S7: CDEF-15-2024 | T7: FORTALECIMIENTO ORGANIZACIONAL | U7: 102790731 | V7: IG 332901003 | W7: 102790731 | X7: 8565894 | AA7: SECRETARÍA_GENERAL | AB7: =IFERROR(VLOOKUP(AA7,Listas!$A$1:$C$14,2,FALSE),"") -> FREDY CÉSPEDES VILLA | AC7: =IFERROR(VLOOKUP(AA7,Listas!$A$1:$C$14,3,FALSE),"") -> 93363483 | AD7: SECRETARÍA_GENERAL | AE7: COORDINADOR(A) GRUPO DE CONTRATACIÓN | AF7: =IFERROR(VLOOKUP(AE7,Listas!$AD$1:$AF$66,2,FALSE),"") -> DIANA BARRERA MEDINA | AG7: =IFERROR(VLOOKUP(AE7,Listas!$AD$1:$AF$65,3,FALSE),"") -> 52964360 | AH7: 1 CONTRATACION DIRECTA | AJ7: 1 SI | AK7: 1 PUBLICADO | AL7: 1 PUBLICADO | AM7: 1 SI | AN7: 34492 | AO7: =IF(YEAR(TODAY())-YEAR(AN7)>100," ",YEAR(TODAY())-YEAR(AN7)) -> 31 | AP7: GRUPO_DE_CONTRATACIÓN | AQ7: LAURA NARANJO | BF7: =BC7+BE7 -> 0 | BI7: =BF7+Q7 -> 361 | BJ7: =IF(BH7="",P7+BF7,BH7) -> 45656 | CC7: =BR7+BV7+BZ7 -> 0 | CE7: =IF(Y7=0,(W7+CC7)-CD7,IF(Y7>0,(Y7+CC7)-CD7)) -> 102790731 | CG7: =IFERROR(IF(((CE7/BI7)*(TODAY()-N7))>CE7,CE7,((CE7/BI7)*(TODAY()-N7))),"") -> 102790731 | CH7: =IF(TODAY()>BJ7,1,+(DAYS360(O7,TODAY())/DAYS360(O7,BJ7))) -> 1 | CI7: =+IF(CL7>0,DAYS360(O7,CL7)/DAYS360(O7,BJ7),CH7) -> 1 | CJ7: =IFERROR(IF(((CG7/CE7)*100)>100,100,((CG7/CE7)*100)),"") -> 100 | CK7: =IFERROR((CF7/CE7)*100,"") -> 0 | CM7: =IF(CL7>1/1/6,"LIQUIDADO",IF(BJ7=0,"",IF(BJ7>=TODAY(),"VIGENTE",IF(BJ7<TODAY(),"TERMINADO",)))) -> TERMINADO | CP7: FEMENINO
A8: 13.27 | B8: 2024-0007 | C8: CTO | D8: CD-007-2024 | E8: 9 PRESTACIÓN DE SERVICIOS | F8: 1 PERSONA NATURAL | G8: 3 CÉDULA DE CIUDADANÍA | H8: 65748384 | I8: INGRID ZULIN PINEDO TOCORA | L8: 13.27 PRESTACIÓN DE SERVICIOS PROFESIONALES COMO ABOGADO PARA APOYAR EL DESARROLLO Y SEGUIMIENTO DE LA ACTIVIDAD CONTRACTUAL EN EL MARCO DEL PROYECTO DE FORTALECIMIENTO ORGANIZACIONAL Y LA IMPLEMENTACIÓN DE LA POLÍTICA DE COMPRAS PÚBLICAS Y DE CONTRATACIÓN DEL ICETEX | M8: BOGOTA | N8: 45294 | O8: 45294 | P8: 45656 | Q8: =P8-O8 -> 362 | R8: 2 INVERSIÓN | S8: CDEF-14-2024 | T8: FORTALECIMIENTO ORGANIZACIONAL | U8: 102790731 | V8: IG 332901003 | W8: 102790731 | X8: 8565894 | AA8: SECRETARÍA_GENERAL | AB8: =IFERROR(VLOOKUP(AA8,Listas!$A$1:$C$14,2,FALSE),"") -> FREDY CÉSPEDES VILLA | AC8: =IFERROR(VLOOKUP(AA8,Listas!$A$1:$C$14,3,FALSE),"") -> 93363483 | AD8: SECRETARÍA_GENERAL | AE8: COORDINADOR(A) GRUPO DE CONTRATACIÓN | AF8: =IFERROR(VLOOKUP(AE8,Listas!$AD$1:$AF$66,2,FALSE),"") -> DIANA BARRERA MEDINA | AG8: =IFERROR(VLOOKUP(AE8,Listas!$AD$1:$AF$65,3,FALSE),"") -> 52964360 | AH8: 1 CONTRATACION DIRECTA | AJ8: 1 SI | AK8: 1 PUBLICADO | AL8: 1 PUBLICADO | AM8: 1 SI | AN8: 25891 | AO8: =IF(YEAR(TODAY())-YEAR(AN8)>100," ",YEAR(TODAY())-YEAR(AN8)) -> 55 | AP8: GRUPO_DE_CONTRATACIÓN | AQ8: LAURA NARANJO | BF8: =BC8+BE8 -> 0 | BI8: =BF8+Q8 -> 362 | BJ8: =IF(BH8="",P8+BF8,BH8) -> 45656 | CC8: =BR8+BV8+BZ8 -> 0 | CE8: =IF(Y8=0,(W8+CC8)-CD8,IF(Y8>0,(Y8+CC8)-CD8)) -> 102790731 | CG8: =IFERROR(IF(((CE8/BI8)*(TODAY()-N8))>CE8,CE8,((CE8/BI8)*(TODAY()-N8))),"") -> 102790731 | CH8: =IF(TODAY()>BJ8,1,+(DAYS360(O8,TODAY())/DAYS360(O8,BJ8))) -> 1 | CI8: =+IF(CL8>0,DAYS360(O8,CL8)/DAYS360(O8,BJ8),CH8) -> 1 | CJ8: =IFERROR(IF(((CG8/CE8)*100)>100,100,((CG8/CE8)*100)),"") -> 100 | CK8: =IFERROR((CF8/CE8)*100,"") -> 0 | CM8: =IF(CL8>1/1/6,"LIQUIDADO",IF(BJ8=0,"",IF(BJ8>=TODAY(),"VIGENTE",IF(BJ8<TODAY(),"TERMINADO",)))) -> TERMINADO | CP8: FEMENINO
A9: 13.29 | B9: 2024-0008 | C9: CTO | D9: CD-008-2024 | E9: 9 PRESTACIÓN DE SERVICIOS | F9: 1 PERSONA NATURAL | G9: 3 CÉDULA DE CIUDADANÍA | H9: 37898247 | I9: DIANA MARÍA GONZALEZ GORDILLO | L9: 13.29 PRESTACIÓN DE SERVICIOS PROFESIONALES COMO ABOGADO PARA APOYAR EL DESARROLLO Y SEGUIMIENTO DE LA ACTIVIDAD CONTRACTUAL EN EL MARCO DEL PROYECTO DE FORTALECIMIENTO ORGANIZACIONAL Y LA IMPLEMENTACIÓN DE LA POLÍTICA DE COMPRAS PÚBLICAS Y DE CONTRATACIÓN DEL ICETEX | M9: BOGOTA | N9: 45294 | O9: 45294 | P9: 45475 | Q9: =P9-O9 -> 181 | R9: 2 INVERSIÓN | S9: CDEF-16-2024 | T9: FORTALECIMIENTO ORGANIZACIONAL | U9: 102790731 | V9: IG 332901003 | W9: 102790731 | X9: 8565894 | AA9: SECRETARÍA_GENERAL | AB9: =IFERROR(VLOOKUP(AA9,Listas!$A$1:$C$14,2,FALSE),"") -> FREDY CÉSPEDES VILLA | AC9: =IFERROR(VLOOKUP(AA9,Listas!$A$1:$C$14,3,FALSE),"") -> 93363483 | AD9: SECRETARÍA_GENERAL | AE9: COORDINADOR(A) GRUPO DE CONTRATACIÓN | AF9: =IFERROR(VLOOKUP(AE9,Listas!$AD$1:$AF$66,2,FALSE),"") -> DIANA BARRERA MEDINA | AG9: =IFERROR(VLOOKUP(AE9,Listas!$AD$1:$AF$65,3,FALSE),"") -> 52964360 | AH9: 1 CONTRATACION DIRECTA | AJ9: 1 SI | AK9: 1 PUBLICADO | AL9: 1 PUBLICADO | AM9: 1 SI | AN9: 29128 | AO9: =IF(YEAR(TODAY())-YEAR(AN9)>100," ",YEAR(TODAY())-YEAR(AN9)) -> 46 | AP9: GRUPO_DE_CONTRATACIÓN | AQ9: LAURA NARANJO | BF9: =BC9+BE9 -> 0 | BI9: =BF9+Q9 -> 181 | BJ9: =IF(BH9="",P9+BF9,BH9) -> 45475 | CC9: =BR9+BV9+BZ9 -> 0 | CE9: =IF(Y9=0,(W9+CC9)-CD9,IF(Y9>0,(Y9+CC9)-CD9)) -> 102790731 | CG9: =IFERROR(IF(((CE9/BI9)*(TODAY()-N9))>CE9,CE9,((CE9/BI9)*(TODAY()-N9))),"") -> 102790731 | CH9: =IF(TODAY()>BJ9,1,+(DAYS360(O9,TODAY())/DAYS360(O9,BJ9))) -> 1 | CI9: =+IF(CL9>0,DAYS360(O9,CL9)/DAYS360(O9,BJ9),CH9) -> 1 | CJ9: =IFERROR(IF(((CG9/CE9)*100)>100,100,((CG9/CE9)*100)),"") -> 100 | CK9: =IFERROR((CF9/CE9)*100,"") -> 0 | CM9: =IF(CL9>1/1/6,"LIQUIDADO",IF(BJ9=0,"",IF(BJ9>=TODAY(),"VIGENTE",IF(BJ9<TODAY(),"TERMINADO",)))) -> TERMINADO | CP9: FEMENINO
A10: 13.30 | B10: 2024-0009 | C10: CTO | D10: CD-009-2024 | E10: 9 PRESTACIÓN DE SERVICIOS | F10: 1 PERSONA NATURAL | G10: 3 CÉDULA DE CIUDADANÍA | H10: 1018405589 | I10: DIANA CAROLINA GUEVARA ESCOBAR | L10: 13.30 PRESTACIÓN DE SERVICIOS PROFESIONALES COMO ABOGADO PARA APOYAR EL DESARROLLO Y SEGUIMIENTO DE LA ACTIVIDAD CONTRACTUAL EN EL MARCO DEL PROYECTO DE FORTALECIMIENTO ORGANIZACIONAL Y LA IMPLEMENTACIÓN DE LA POLÍTICA DE COMPRAS PÚBLICAS Y DE CONTRATACIÓN DEL ICETEX | M10: BOGOTA | N10: 45294 | O10: 45295 | P10: 45656 | Q10: =P10-O10 -> 361 | R10: 2 INVERSIÓN | S10: CDEF-17-2024 | T10: FORTALECIMIENTO ORGANIZACIONAL | U10: 102790731 | V10: IG 332901003 | W10: 102790731 | X10: 8565894 | AA10: SECRETARÍA_GENERAL | AB10: =IFERROR(VLOOKUP(AA10,Listas!$A$1:$C$14,2,FALSE),"") -> FREDY CÉSPEDES VILLA | AC10: =IFERROR(VLOOKUP(AA10,Listas!$A$1:$C$14,3,FALSE),"") -> 93363483 | AD10: SECRETARÍA_GENERAL | AE10: COORDINADOR(A) GRUPO DE CONTRATACIÓN | AF10: =IFERROR(VLOOKUP(AE10,Listas!$AD$1:$AF$66,2,FALSE),"") -> DIANA BARRERA MEDINA | AG10: =IFERROR(VLOOKUP(AE10,Listas!$AD$1:$AF$65,3,FALSE),"") -> 52964360 | AH10: 1 CONTRATACION DIRECTA | AJ10: 1 SI | AK10: 1 PUBLICADO | AL10: 1 PUBLICADO | AM10: 1 SI | AN10: 28650 | AO10: =IF(YEAR(TODAY())-YEAR(AN10)>100," ",YEAR(TODAY())-YEAR(AN10)) -> 47 | AP10: GRUPO_DE_CONTRATACIÓN | AQ10: LAURA NARANJO | BF10: =BC10+BE10 -> 0 | BI10: =BF10+Q10 -> 361 | BJ10: =IF(BH10="",P10+BF10,BH10) -> 45656 | CC10: =BR10+BV10+BZ10 -> 0 | CE10: =IF(Y10=0,(W10+CC10)-CD10,IF(Y10>0,(Y10+CC10)-CD10)) -> 102790731 | CG10: =IFERROR(IF(((CE10/BI10)*(TODAY()-N10))>CE10,CE10,((CE10/BI10)*(TODAY()-N10))),"") -> 102790731 | CH10: =IF(TODAY()>BJ10,1,+(DAYS360(O10,TODAY())/DAYS360(O10,BJ10))) -> 1 | CI10: =+IF(CL10>0,DAYS360(O10,CL10)/DAYS360(O10,BJ10),CH10) -> 1 | CJ10: =IFERROR(IF(((CG10/CE10)*100)>100,100,((CG10/CE10)*100)),"") -> 100 | CK10: =IFERROR((CF10/CE10)*100,"") -> 0 | CM10: =IF(CL10>1/1/6,"LIQUIDADO",IF(BJ10=0,"",IF(BJ10>=TODAY(),"VIGENTE",IF(BJ10<TODAY(),"TERMINADO",)))) -> TERMINADO | CP10: FEMENINO
A11: 13.34 | B11: 2024-0010 | C11: CTO | D11: CD-010-2024 | E11: 9 PRESTACIÓN DE SERVICIOS | F11: 1 PERSONA NATURAL | G11: 3 CÉDULA DE CIUDADANÍA | H11: 79855988 | I11: JOSE GREGORIO SARMIENTO ORTIZ | L11: 13.34 PRESTACIÓN DE SERVICIOS PROFESIONALES COMO ABOGADO PARA APOYAR EL DESARROLLO Y SEGUIMIENTO DE LA ACTIVIDAD CONTRACTUAL EN EL MARCO DEL PROYECTO DE FORTALECIMIENTO ORGANIZACIONAL Y LA IMPLEMENTACIÓN DE LA POLÍTICA DE COMPRAS PÚBLICAS Y DE CONTRATACIÓN DEL ICETEX | M11: BOGOTA | N11: 45293 | O11: 45294 | P11: 45656 | Q11: =P11-O11 -> 362 | R11: 2 INVERSIÓN | S11: CDEF-20-2024 | T11: FORTALECIMIENTO ORGANIZACIONAL | U11: 102790731 | V11: IG 332901003 | W11: 102790731 | X11: 8565894 | AA11: SECRETARÍA_GENERAL | AB11: =IFERROR(VLOOKUP(AA11,Listas!$A$1:$C$14,2,FALSE),"") -> FREDY CÉSPEDES VILLA | AC11: =IFERROR(VLOOKUP(AA11,Listas!$A$1:$C$14,3,FALSE),"") -> 93363483 | AD11: SECRETARÍA_GENERAL | AE11: COORDINADOR(A) GRUPO DE CONTRATACIÓN | AF11: =IFERROR(VLOOKUP(AE11,Listas!$AD$1:$AF$66,2,FALSE),"") -> DIANA BARRERA MEDINA | AG11: =IFERROR(VLOOKUP(AE11,Listas!$AD$1:$AF$65,3,FALSE),"") -> 52964360 | AH11: 1 CONTRATACION DIRECTA | AJ11: 1 SI | AK11: 1 PUBLICADO | AL11: 1 PUBLICADO | AM11: 1 SI | AN11: 28874 | AO11: =IF(YEAR(TODAY())-YEAR(AN11)>100," ",YEAR(TODAY())-YEAR(AN11)) -> 46 | AP11: GRUPO_DE_CONTRATACIÓN | AQ11: LAURA NARANJO | BF11: =BC11+BE11 -> 0 | BI11: =BF11+Q11 -> 362 | BJ11: =IF(BH11="",P11+BF11,BH11) -> 45656 | CC11: =BR11+BV11+BZ11 -> 0 | CE11: =IF(Y11=0,(W11+CC11)-CD11,IF(Y11>0,(Y11+CC11)-CD11)) -> 102790731 | CG11: =IFERROR(IF(((CE11/BI11)*(TODAY()-N11))>CE11,CE11,((CE11/BI11)*(TODAY()-N11))),"") -> 102790731 | CH11: =IF(TODAY()>BJ11,1,+(DAYS360(O11,TODAY())/DAYS360(O11,BJ11))) -> 1 | CI11: =+IF(CL11>0,DAYS360(O11,CL11)/DAYS360(O11,BJ11),CH11) -> 1 | CJ11: =IFERROR(IF(((CG11/CE11)*100)>100,100,((CG11/CE11)*100)),"") -> 100 | CK11: =IFERROR((CF11/CE11)*100,"") -> 0 | CM11: =IF(CL11>1/1/6,"LIQUIDADO",IF(BJ11=0,"",IF(BJ11>=TODAY(),"VIGENTE",IF(BJ11<TODAY(),"TERMINADO",)))) -> TERMINADO | CP11: MASCULINO
A12: 13.35 | B12: 2024-0011 | C12: CTO | D12: CD-011-2024 | E12: 9 PRESTACIÓN DE SERVICIOS | F12: 1 PERSONA NATURAL | G12: 3 CÉDULA DE CIUDADANÍA | H12: 1075291011 | I12: JUAN CAMILO CEDIEL BORRERO | L12: 13.35 PRESTACIÓN DE SERVICIOS PROFESIONALES COMO ABOGADO PARA APOYAR EL DESARROLLO Y SEGUIMIENTO DE LA ACTIVIDAD CONTRACTUAL EN EL MARCO DEL PROYECTO DE FORTALECIMIENTO ORGANIZACIONAL Y LA IMPLEMENTACIÓN DE LA POLÍTICA DE COMPRAS PÚBLICAS Y DE CONTRATACIÓN DEL ICETEX | M12: BOGOTA | N12: 45293 | O12: 45294 | P12: 45656 | Q12: =P12-O12 -> 362 | R12: 2 INVERSIÓN | S12: CDEF-21-2024 | T12: FORTALECIMIENTO ORGANIZACIONAL | U12: 102790731 | V12: IG 332901003 | W12: 102790731 | X12: 8565894 | AA12: SECRETARÍA_GENERAL | AB12: =IFERROR(VLOOKUP(AA12,Listas!$A$1:$C$14,2,FALSE),"") -> FREDY CÉSPEDES VILLA | AC12: =IFERROR(VLOOKUP(AA12,Listas!$A$1:$C$14,3,FALSE),"") -> 93363483 | AD12: SECRETARÍA_GENERAL | AE12: COORDINADOR(A) GRUPO DE CONTRATACIÓN | AF12: =IFERROR(VLOOKUP(AE12,Listas!$AD$1:$AF$66,2,FALSE),"") -> DIANA BARRERA MEDINA | AG12: =IFERROR(VLOOKUP(AE12,Listas!$AD$1:$AF$65,3,FALSE),"") -> 52964360 | AH12: 1 CONTRATACION DIRECTA | AJ12: 1 SI | AK12: 1 PUBLICADO | AL12: 1 PUBLICADO | AM12: 1 SI | AN12: 34943 | AO12: =IF(YEAR(TODAY())-YEAR(AN12)>100," ",YEAR(TODAY())-YEAR(AN12)) -> 30 | AP12: GRUPO_DE_CONTRATACIÓN | AQ12: LAURA NARANJO | BF12: =BC12+BE12 -> 0 | BI12: =BF12+Q12 -> 362 | BJ12: =IF(BH12="",P12+BF12,BH12) -> 45656 | CC12: =BR12+BV12+BZ12 -> 0 | CE12: =IF(Y12=0,(W12+CC12)-CD12,IF(Y12>0,(Y12+CC12)-CD12)) -> 102790731 | CG12: =IFERROR(IF(((CE12/BI12)*(TODAY()-N12))>CE12,CE12,((CE12/BI12)*(TODAY()-N12))),"") -> 102790731 | CH12: =IF(TODAY()>BJ12,1,+(DAYS360(O12,TODAY())/DAYS360(O12,BJ12))) -> 1 | CI12: =+IF(CL12>0,DAYS360(O12,CL12)/DAYS360(O12,BJ12),CH12) -> 1 | CJ12: =IFERROR(IF(((CG12/CE12)*100)>100,100,((CG12/CE12)*100)),"") -> 100 | CK12: =IFERROR((CF12/CE12)*100,"") -> 0 | CM12: =IF(CL12>1/1/6,"LIQUIDADO",IF(BJ12=0,"",IF(BJ12>=TODAY(),"VIGENTE",IF(BJ12<TODAY(),"TERMINADO",)))) -> TERMINADO | CP12: MASCULINO
A13: 13.36 | B13: 2024-0012 | C13: CTO | D13: CD-012-2024 | E13: 9 PRESTACIÓN DE SERVICIOS | F13: 1 PERSONA NATURAL | G13: 3 CÉDULA DE CIUDADANÍA | H13: 80161275 | I13: BRESMAN GUSTAVO SANCHEZ OSPINA | L13: 13.36 PRESTACIÓN DE SERVICIOS PROFESIONALES COMO ABOGADO PARA APOYAR EL DESARROLLO Y SEGUIMIENTO DE LA ACTIVIDAD CONTRACTUAL EN EL MARCO DEL PROYECTO DE FORTALECIMIENTO ORGANIZACIONAL Y LA IMPLEMENTACIÓN DE LA POLÍTICA DE COMPRAS PÚBLICAS Y DE CONTRATACIÓN DEL ICETEX | M13: BOGOTA | N13: 45293 | O13: 45294 | P13: 45656 | Q13: =P13-O13 -> 362 | R13: 2 INVERSIÓN | S13: CDEF-22-2024 | T13: FORTALECIMIENTO ORGANIZACIONAL | U13: 102790731 | V13: IG 332901003 | W13: 102790731 | X13: 8565894 | AA13: SECRETARÍA_GENERAL | AB13: =IFERROR(VLOOKUP(AA13,Listas!$A$1:$C$14,2,FALSE),"") -> FREDY CÉSPEDES VILLA | AC13: =IFERROR(VLOOKUP(AA13,Listas!$A$1:$C$14,3,FALSE),"") -> 93363483 | AD13: SECRETARÍA_GENERAL | AE13: COORDINADOR(A) GRUPO DE CONTRATACIÓN | AF13: =IFERROR(VLOOKUP(AE13,Listas!$AD$1:$AF$66,2,FALSE),"") -> DIANA BARRERA MEDINA | AG13: =IFERROR(VLOOKUP(AE13,Listas!$AD$1:$AF$65,3,FALSE),"") -> 52964360 | AH13: 1 CONTRATACION DIRECTA | AJ13: 1 SI | AK13: 1 PUBLICADO | AL13: 1 PUBLICADO | AM13: 1 SI | AN13: 30344 | AO13: =IF(YEAR(TODAY())-YEAR(AN13)>100," ",YEAR(TODAY())-YEAR(AN13)) -> 42 | AP13: GRUPO_DE_CONTRATACIÓN | AQ13: LAURA NARANJO | BF13: =BC13+BE13 -> 0 | BI13: =BF13+Q13 -> 362 | BJ13: =IF(BH13="",P13+BF13,BH13) -> 45656 | CC13: =BR13+BV13+BZ13 -> 0 | CE13: =IF(Y13=0,(W13+CC13)-CD13,IF(Y13>0,(Y13+CC13)-CD13)) -> 102790731 | CG13: =IFERROR(IF(((CE13/BI13)*(TODAY()-N13))>CE13,CE13,((CE13/BI13)*(TODAY()-N13))),"") -> 102790731 | CH13: =IF(TODAY()>BJ13,1,+(DAYS360(O13,TODAY())/DAYS360(O13,BJ13))) -> 1 | CI13: =+IF(CL13>0,DAYS360(O13,CL13)/DAYS360(O13,BJ13),CH13) -> 1 | CJ13: =IFERROR(IF(((CG13/CE13)*100)>100,100,((CG13/CE13)*100)),"") -> 100 | CK13: =IFERROR((CF13/CE13)*100,"") -> 0 | CM13: =IF(CL13>1/1/6,"LIQUIDADO",IF(BJ13=0,"",IF(BJ13>=TODAY(),"VIGENTE",IF(BJ13<TODAY(),"TERMINADO",)))) -> TERMINADO | CP13: MASCULINO
... A16: 13.26 | B16: 2024-0015 | C16: CTO | D16: CD-015-2024 | E16: 9 PRESTACIÓN DE SERVICIOS | F16: 1 PERSONA NATURAL | G16: 3 CÉDULA DE CIUDADANÍA | H16: 1128063454 | I16: DIANA PATRICIA JALLER BUSTILLO | L16: 13.26 PRESTACIÓN DE SERVICIOS PROFESIONALES COMO ABOGADO PARA APOYAR EL DESARROLLO Y SEGUIMIENTO DE LA ACTIVIDAD CONTRACTUAL EN EL MARCO DEL PROYECTO DE FORTALECIMIENTO ORGANIZACIONAL Y LA IMPLEMENTACIÓN DE LA POLÍTICA DE COMPRAS PÚBLICAS Y DE CONTRATACIÓN DEL ICETEX | M16: BOGOTA | N16: 45294 | O16: 45294 | P16: 45476 | Q16: =P16-O16 -> 182 | R16: 2 INVERSIÓN | S16: CDEF-13-2024 | T16: FORTALECIMIENTO ORGANIZACIONAL | U16: 102790731 | V16: IG 332901003 | W16: 102790731 | X16: 8565894 | AA16: SECRETARÍA_GENERAL | AB16: =IFERROR(VLOOKUP(AA16,Listas!$A$1:$C$14,2,FALSE),"") -> FREDY CÉSPEDES VILLA | AC16: =IFERROR(VLOOKUP(AA16,Listas!$A$1:$C$14,3,FALSE),"") -> 93363483 | AD16: SECRETARÍA_GENERAL | AE16: COORDINADOR(A) GRUPO DE CONTRATACIÓN | AF16: =IFERROR(VLOOKUP(AE16,Listas!$AD$1:$AF$66,2,FALSE),"") -> DIANA BARRERA MEDINA | AG16: =IFERROR(VLOOKUP(AE16,Listas!$AD$1:$AF$65,3,FALSE),"") -> 52964360 | AH16: 1 CONTRATACION DIRECTA | AJ16: 1 SI | AK16: 1 PUBLICADO | AL16: 1 PUBLICADO | AM16: 1 SI | AN16: 32393 | AO16: =IF(YEAR(TODAY())-YEAR(AN16)>100," ",YEAR(TODAY())-YEAR(AN16)) -> 37 | AP16: GRUPO_DE_CONTRATACIÓN | AQ16: LAURA NARANJO | BF16: =BC16+BE16 -> 0 | BI16: =BF16+Q16 -> 182 | BJ16: =IF(BH16="",P16+BF16,BH16) -> 45476 | CC16: =BR16+BV16+BZ16 -> 0 | CE16: =IF(Y16=0,(W16+CC16)-CD16,IF(Y16>0,(Y16+CC16)-CD16)) -> 102790731 | CG16: =IFERROR(IF(((CE16/BI16)*(TODAY()-N16))>CE16,CE16,((CE16/BI16)*(TODAY()-N16))),"") -> 102790731 | CH16: =IF(TODAY()>BJ16,1,+(DAYS360(O16,TODAY())/DAYS360(O16,BJ16))) -> 1 | CI16: =+IF(CL16>0,DAYS360(O16,CL16)/DAYS360(O16,BJ16),CH16) -> 1 | CJ16: =IFERROR(IF(((CG16/CE16)*100)>100,100,((CG16/CE16)*100)),"") -> 100 | CK16: =IFERROR((CF16/CE16)*100,"") -> 0 | CM16: =IF(CL16>1/1/6,"LIQUIDADO",IF(BJ16=0,"",IF(BJ16>=TODAY(),"VIGENTE",IF(BJ16<TODAY(),"TERMINADO",)))) -> TERMINADO | CP16: FEMENINO
A17: 12.20 | B17: 2024-0016 | C17: CTO | D17: CD-016-2024 | E17: 9 PRESTACIÓN DE SERVICIOS | F17: 1 PERSONA NATURAL | G17: 3 CÉDULA DE CIUDADANÍA | H17: 1015408521 | I17: GISSET XIMENA BARRETO VILLAMIL | L17: PRESTAR LOS SERVICIOS PROFESIONALES ESPECIALIZADOS EN LA MEJORA DE LOS PROCESOS PRESUPUESTALES ENFOCADOS EN LA PLANEACIÓN, DISEÑO Y DESARROLLO DE MECANISMOS QUE PERMITAN LA INTEGRACIÓN Y EL ANÁLISIS DE INFORMACIÓN PRESUPUESTAL EN EL MARCO DEL PROYECTO DE INVERSIÓN DE BANCA ABIERTA Y TRANSPARENTE E INHOUSE BANKING. | M17: BOGOTA | N17: 45294 | O17: 45294 | P17: 45657 | Q17: =P17-O17 -> 363 | R17: 2 INVERSIÓN | S17: CDEF-05-2024 | T17: BANCA ABIERTA Y TRANSPARENTE E INHOUSE B | U17: 92883552 | V17: IG332902005 | W17: 92883552 | X17: 7740296 | AA17: SECRETARÍA_GENERAL | AB17: =IFERROR(VLOOKUP(AA17,Listas!$A$1:$C$14,2,FALSE),"") -> FREDY CÉSPEDES VILLA | AC17: =IFERROR(VLOOKUP(AA17,Listas!$A$1:$C$14,3,FALSE),"") -> 93363483 | AD17: VICEPRESIDENCIA_FINANCIERA | AE17: COORDINADOR(A) GRUPO DE PRESUPUESTO | AF17: =IFERROR(VLOOKUP(AE17,Listas!$AD$1:$AF$66,2,FALSE),"") -> GISSET XIMENA BARRETO VILLAMIL | AG17: =IFERROR(VLOOKUP(AE17,Listas!$AD$1:$AF$65,3,FALSE),"") -> 1015408521 | AH17: 1 CONTRATACION DIRECTA | AI17: Apoyar en la estructuración de mecanismos de registro, seguimiento y control de operaciones presupuestales relacionadas con vigencias futuras, acorde a los procedimientos establecidos y requeridos en el marco de la modernización de las funciones financieras del Instituto. 2. Proponer iniciativas que propendan por la articulación de actores para la apropiación e implementación de mecanismos para la optimización de los procesos que soportan la operación financiera del Instituto, con especial énfasis en el seguimiento y control de vigencias futuras. 3. Apoyar en el seguimiento y control de los requerimientos relacionados con la mitigación de riesgos del proceso de Gestión Presupuestal, los planes de mejoramiento y los lineamientos impartidos en el marco del proyecto de inversión de banca abierta y transparente. 4. Apoyar la estructuración de insumos técnicos para dar respuesta a los requerimientos de información solicitados por entes internos y/o externos en el marco de los proyectos de inversión Inhouse Banking, 5. Apoyar en la estructuración y conceptualización técnica de iniciativas que permitan la simplificación, estandarización e integración de procesos de la gestión presupuestal del ICETEX en el marco del proyecto de inversión de banca abierta y transparente e In House Banking. 6. Apoyar el diseño, apropiación e implementación de mecanismos para la optimización de los procesos presupuestales que se adelantan en el marco de la modernización de las funciones financieras del Instituto. 7. Apoyar la apropiación e implementación de esquemas de reporte y control a la gestión presupuestal del Instituto en el marco del proyecto de inversión de banca abierta y Código: F451 ESTUDIO PREVIO SIMPLIFICADO Versión: 3 Fecha: 04/12/2023 Página 7 de 13 transparente. 8. Analizar la información generada a partir de las bases de datos presupuestales con el fin de verificar su fidelidad. 9. Las demás obligaciones que se requieran para el cumplimiento a cabalidad del objeto contractual y que sean inherentes a la naturaleza del contrato. 10. Cumplir con los indicadores de gestión establecidos. | AJ17: 1 SI | AK17: 1 PUBLICADO | AL17: 1 PUBLICADO | AM17: 1 SI | AO17: =IF(YEAR(TODAY())-YEAR(AN17)>100," ",YEAR(TODAY())-YEAR(AN17)) | AP17: GRUPO_DE_CONTRATACIÓN | AQ17: SEBASTIAN AYALA | AR17: 45552 | AS17: WILLIAM ALEXANDER VALENCIA NEMOCON | AT17: 80119997 | AU17: PRESTAR LOS SERVICIOS PROFESIONALES ESPECIALIZADOS EN LA MEJORA DE LOS PROCESOS PRESUPUESTALES ENFOCADOS EN LA PLANEACIÓN, DISEÑO Y DESARROLLO DE MECANISMOS QUE PERMITAN LA INTEGRACIÓN Y EL ANÁLISIS DE INFORMACIÓN PRESUPUESTAL EN EL MARCO DEL PROYECTO DE INVERSIÓN DE BANCA ABIERTA Y TRANSPARENTE E INHOUSE BANKING. | AV17: 27091036 | BF17: =BC17+BE17 -> 0 | BI17: =BF17+Q17 -> 363 | BJ17: =IF(BH17="",P17+BF17,BH17) -> 45657 | CC17: =BR17+BV17+BZ17 -> 0 | CE17: =IF(Y17=0,(W17+CC17)-CD17,IF(Y17>0,(Y17+CC17)-CD17)) -> 92883552 | CG17: =IFERROR(IF(((CE17/BI17)*(TODAY()-N17))>CE17,CE17,((CE17/BI17)*(TODAY()-N17))),"") -> 92883552 | CH17: =IF(TODAY()>BJ17,1,+(DAYS360(O17,TODAY())/DAYS360(O17,BJ17))) -> 1 | CI17: =+IF(CL17>0,DAYS360(O17,CL17)/DAYS360(O17,BJ17),CH17) -> 1 | CJ17: =IFERROR(IF(((CG17/CE17)*100)>100,100,((CG17/CE17)*100)),"") -> 100 | CK17: =IFERROR((CF17/CE17)*100,"") -> 0 | CM17: =IF(CL17>1/1/6,"LIQUIDADO",IF(BJ17=0,"",IF(BJ17>=TODAY(),"VIGENTE",IF(BJ17<TODAY(),"TERMINADO",)))) -> TERMINADO | CO17: 20243030000152-I Id: 4085611 | CP17: FEMENINO
A18: 12.19 | B18: 2024-0017 | C18: CTO | D18: CD-017-2024 | E18: 9 PRESTACIÓN DE SERVICIOS | F18: 1 PERSONA NATURAL | G18: 3 CÉDULA DE CIUDADANÍA | H18: 80119997 | I18: WILLIAM ALEXANDER VALENCIA NEMOCON | L18: PRESTAR LOS SERVICIOS PROFESIONALES EN LA ESTRUCTURACIÓN DE INICIATIVAS PARA LA OPTIMIZACIÓN DE MECANISMOS DE ADMINISTRACIÓN DE LOS SISTEMAS DE GESTIÓN PRESUPUESTAL Y SUS BASES DE DATOS EN EL MARCO DEL PROYECTO DE INVERSIÓN DE BANCA ABIERTA Y TRANSPARENTE E INHOUSE BANKING. | M18: BOGOTA | N18: 45294 | O18: 45294 | P18: 45657 | Q18: =P18-O18 -> 363 | R18: 2 INVERSIÓN | S18: CDEF-04-2024 | T18: BANCA ABIERTA Y TRANSPARENTE E INHOUSE B | U18: 66012000 | V18: IG332902005 | W18: 66012000 | X18: 5501000 | AA18: SECRETARÍA_GENERAL | AB18: =IFERROR(VLOOKUP(AA18,Listas!$A$1:$C$14,2,FALSE),"") -> FREDY CÉSPEDES VILLA | AC18: =IFERROR(VLOOKUP(AA18,Listas!$A$1:$C$14,3,FALSE),"") -> 93363483 | AD18: VICEPRESIDENCIA_FINANCIERA | AE18: COORDINADOR(A) GRUPO DE PRESUPUESTO | AF18: =IFERROR(VLOOKUP(AE18,Listas!$AD$1:$AF$66,2,FALSE),"") -> GISSET XIMENA BARRETO VILLAMIL | AG18: =IFERROR(VLOOKUP(AE18,Listas!$AD$1:$AF$65,3,FALSE),"") -> 1015408521 | AH18: 1 CONTRATACION DIRECTA | AI18: 1. Apoyar en la estructuración de mecanismos de registro, seguimiento y control de operaciones presupuestales relacionadas con vigencias futuras, acorde a los procedimientos establecidos y requeridos en el marco de la modernización de las funciones financieras del Instituto. 2. Proponer iniciativas que propendan por la articulación de actores para la apropiación e implementación de mecanismos para la optimización de los procesos que soportan la operación financiera del Instituto, con especial énfasis en el seguimiento y control de vigencias futuras. 3. Apoyar en el seguimiento y control de los requerimientos relacionados con la mitigación de riesgos del proceso de Gestión Presupuestal, los planes de mejoramiento y los lineamientos impartidos en el marco del proyecto de inversión de banca abierta y transparente. 4. Apoyar la estructuración de insumos técnicos para dar respuesta a los requerimientos de información solicitados por entes internos y/o externos en el marco de los proyectos de inversión Inhouse Banking, 5. Apoyar en la estructuración y conceptualización técnica de iniciativas que permitan la simplificación, estandarización e integración de procesos de la gestión presupuestal del ICETEX en el marco del proyecto de inversión de banca abierta y transparente e In House Banking. 6. Apoyar el diseño, apropiación e implementación de mecanismos para la optimización de los procesos presupuestales que se adelantan en el marco de la modernización de las funciones financieras del Instituto. 7. Apoyar la apropiación e implementación de esquemas de reporte y control a la gestión presupuestal del Instituto en el marco del proyecto de inversión de banca abierta y transparente. 8. Analizar la información generada a partir de las bases de datos presupuestales con el fin de verificar su fidelidad. 9. Las demás obligaciones que se requieran para el cumplimiento a cabalidad del objeto contractual y que sean inherentes a la naturaleza del contrato. 10. Cumplir con los indicadores de gestión establecidos | AJ18: 1 SI | AK18: 1 PUBLICADO | AL18: 1 PUBLICADO | AM18: 1 SI | AO18: =IF(YEAR(TODAY())-YEAR(AN18)>100," ",YEAR(TODAY())-YEAR(AN18)) | AP18: GRUPO_DE_CONTRATACIÓN | AQ18: SEBASTIAN AYALA | BF18: =BC18+BE18 -> 0 | BH18: 45555 | BI18: =BF18+Q18 -> 363 | BJ18: =IF(BH18="",P18+BF18,BH18) -> 45555 | CC18: =BR18+BV18+BZ18 -> 0 | CE18: =IF(Y18=0,(W18+CC18)-CD18,IF(Y18>0,(Y18+CC18)-CD18)) -> 66012000 | CF18: 49645388 | CG18: =IFERROR(IF(((CE18/BI18)*(TODAY()-N18))>CE18,CE18,((CE18/BI18)*(TODAY()-N18))),"") -> 66012000 | CH18: =IF(TODAY()>BJ18,1,+(DAYS360(O18,TODAY())/DAYS360(O18,BJ18))) -> 1 | CI18: =+IF(CL18>0,DAYS360(O18,CL18)/DAYS360(O18,BJ18),CH18) -> 1 | CJ18: =IFERROR(IF(((CG18/CE18)*100)>100,100,((CG18/CE18)*100)),"") -> 100 | CK18: =IFERROR((CF18/CE18)*100,"") -> 75.206611 | CM18: =IF(CL18>1/1/6,"LIQUIDADO",IF(BJ18=0,"",IF(BJ18>=TODAY(),"VIGENTE",IF(BJ18<TODAY(),"TERMINADO",)))) -> TERMINADO | CO18: 20243030000154-I Id: 4085614 | CP18: MASCULINO
A19: 13.39 | B19: 2024-0018 | C19: CTO | D19: CD-018-2024 | E19: 9 PRESTACIÓN DE SERVICIOS | F19: 1 PERSONA NATURAL | G19: 3 CÉDULA DE CIUDADANÍA | H19: 1077940566 | I19: RAUL ALFREDO QUEVEDO | L19: PRESTACIÓN DE SERVICIOS DE APOYO TÉCNICO A LA GESTIÓN DE LA POLÍTICA DE COMPRAS PÚBLICAS Y DE CONTRATACIÓN EN EL MARCO DEL PROYECTO DENOMINADO “FORTALECIMIENTO ORGANIZACIONAL" DEL ICETEX | M19: BOGOTA | N19: 45294 | O19: 45294 | P19: 45656 | Q19: =P19-O19 -> 362 | R19: 2 INVERSIÓN | S19: CDEF-25-2024 | T19: FORTALECIMIENTO ORGANIZACIONAL | U19: 51759243 | V19: IG 332901003 | W19: 51759240 | X19: 4313270 | AA19: SECRETARÍA_GENERAL | AB19: =IFERROR(VLOOKUP(AA19,Listas!$A$1:$C$14,2,FALSE),"") -> FREDY CÉSPEDES VILLA | AC19: =IFERROR(VLOOKUP(AA19,Listas!$A$1:$C$14,3,FALSE),"") -> 93363483 | AD19: SECRETARÍA_GENERAL | AE19: COORDINADOR(A) GRUPO DE CONTRATACIÓN | AF19: =IFERROR(VLOOKUP(AE19,Listas!$AD$1:$AF$66,2,FALSE),"") -> DIANA BARRERA MEDINA | AG19: =IFERROR(VLOOKUP(AE19,Listas!$AD$1:$AF$65,3,FALSE),"") -> 52964360 | AH19: 1 CONTRATACION DIRECTA | AI19: 1. Proyectar comunicaciones para atender los requerimientos internos y externos relacionados con las actividades desarrolladas por el grupo de contratos, así como los requerimientos de los entes de control, en el marco del proyecto de inversión. 2. Realizar la radicación de documentos, así́ como el direccionamiento respectivo, de conformidad con lo establecido en los procedimientos del Grupo de Contratación de acuerdo con el objeto contractual. 3. Servir como canal de comunicación con el área de gestión documental para gestionar la consecución de expedientes, documentos y de toda la información que requiera el Grupo de Contratación y en general de la Secretaria General en cumplimiento de la política de MIPG. 4. Apoyar en la actualización, clasificación y organización de los documentos físicos y virtuales propios de los procesos del grupo de contratos y en la actualización de la base de datos del grupo de contratos, así como brindar información respecto de la misma, de conformidad con las metas y objetivos del proyecto de inversión. 5. Apoyar en la vinculación, creación y revisión de las hojas de vida del SIGEP, alineados con las metas del proyecto de inversión en pro del fortalecimiento organizacional. 6. Elaborar los informes y reportes previa coordinación con el supervisor del contrato de acuerdo con las actividades y procesos realizados en el Grupo de Contratación en el marco del objeto contractual. 7. Adelantar los tramites a cargo, en el marco del proyecto de fortalecimiento organizacional y la implementación de la política de compras públicas y de contratación, promoviendo el cierre de brechas que se presenten. 8. Las demás obligaciones que sean asignadas por quien ejerza la función de la supervisión del contrato. | AJ19: 1 SI | AK19: 1 PUBLICADO | AL19: 1 PUBLICADO | AM19: 1 SI | AN19: 31906 | AO19: =IF(YEAR(TODAY())-YEAR(AN19)>100," ",YEAR(TODAY())-YEAR(AN19)) -> 38 | AP19: GRUPO_DE_CONTRATACIÓN | AQ19: LAURA NARANJO | BF19: =BC19+BE19 -> 0 | BI19: =BF19+Q19 -> 362 | BJ19: =IF(BH19="",P19+BF19,BH19) -> 45656 | CC19: =BR19+BV19+BZ19 -> 0 | CE19: =IF(Y19=0,(W19+CC19)-CD19,IF(Y19>0,(Y19+CC19)-CD19)) -> 51759240 | CG19: =IFERROR(IF(((CE19/BI19)*(TODAY()-N19))>CE19,CE19,((CE19/BI19)*(TODAY()-N19))),"") -> 51759240 | CH19: =IF(TODAY()>BJ19,1,+(DAYS360(O19,TODAY())/DAYS360(O19,BJ19))) -> 1 | CI19: =+IF(CL19>0,DAYS360(O19,CL19)/DAYS360(O19,BJ19),CH19) -> 1 | CJ19: =IFERROR(IF(((CG19/CE19)*100)>100,100,((CG19/CE19)*100)),"") -> 100 | CK19: =IFERROR((CF19/CE19)*100,"") -> 0 | CM19: =IF(CL19>1/1/6,"LIQUIDADO",IF(BJ19=0,"",IF(BJ19>=TODAY(),"VIGENTE",IF(BJ19<TODAY(),"TERMINADO",)))) -> TERMINADO | CP19: MASCULINO
A20: 12.18 | B20: 2024-0019 | C20: CTO | D20: CD-019-2024 | E20: 9 PRESTACIÓN DE SERVICIOS | F20: 1 PERSONA NATURAL | G20: 3 CÉDULA DE CIUDADANÍA | H20: 53030016 | I20: MARITZA ALEXANDRA CAICEDO GONZALEZ | L20: PRESTAR LOS SERVICIOS PROFESIONALES EN LA ACTUALIZACIÓN DE LOS SISTEMAS DE GESTIÓN PRESUPUESTAL DE LOS RECURSOS DE FONDOS Y PROPIOS Y EN EL PROCESO DE VALIDACIÓN DE LA EJECUCIÓN DEL PRESUPUESTO A PARTIR DEL PROCESAMIENTO Y ANÁLISIS DE LA INFORMACIÓN A CARGO DEL GRUPO DE PRESUPUESTO. | M20: BOGOTA | N20: 45294 | O20: 45294 | P20: 45657 | Q20: =P20-O20 -> 363 | R20: 1 FUNCIONAMIENTO | S20: CDEF-03-2024 | T20: HONORARIOS - VFN | U20: 55908468 | V20: IG312001020400012 | W20: 55908468 | X20: 4659039 | AA20: SECRETARÍA_GENERAL | AB20: =IFERROR(VLOOKUP(AA20,Listas!$A$1:$C$14,2,FALSE),"") -> FREDY CÉSPEDES VILLA | AC20: =IFERROR(VLOOKUP(AA20,Listas!$A$1:$C$14,3,FALSE),"") -> 93363483 | AD20: VICEPRESIDENCIA_FINANCIERA | AE20: COORDINADOR(A) GRUPO DE PRESUPUESTO | AF20: =IFERROR(VLOOKUP(AE20,Listas!$AD$1:$AF$66,2,FALSE),"") -> GISSET XIMENA BARRETO VILLAMIL | AG20: =IFERROR(VLOOKUP(AE20,Listas!$AD$1:$AF$65,3,FALSE),"") -> 1015408521 | AH20: 1 CONTRATACION DIRECTA | AI20: 1. Apoyar la actualización, sistematización y soporte a las bases de datos de los sistemas o aplicativos de información relacionados con la gestión presupuestal de los recursos de fondos y propios. 2. Apoyar la gestión de seguimiento y control de la información relacionada con los recursos en administración y propios en tiempo real para la generación de estadísticas de la operación. 3. Apoyar en el seguimiento a la ejecución presupuestal de los contratos del Instituto en las bases de datos del Grupo de Presupuesto frente a los registros en el aplicativo financiero, a través de la generación de reportes, depuración y validación de información. 4. Apoyar la gestión de los registros presupuestales requeridos relacionados con los recursos de propios y de fondos acorde a los procedimientos establecidos, con el objetivo de garantizar la calidad de la información. 5. Apoyar la implementación y apropiación de las solicitudes de los aplicativos que soportan la gestión presupuestal del Instituto. 6. Apoyar en la verificación de los contratos y condiciones de fondos en administración con el fin de obtener la información fuente para la gestión presupuestal de la mencionada fuente de recursos. 7. Apoyar la gestión de seguimiento y control de la información a través de la validación y registro de órdenes de pago de recursos propios y de fondos. 8. Apoyar la gestión de seguimiento y control de la información relacionada a recursos Propios acorde a los procedimientos establecidos, requeridos en el marco de la modernización de las funciones financieras del Instituto para garantizar el adecuado manejo de los registros presupuestales correspondientes. 9. Apoyar la gestión de seguimiento y control presupuestal de los giros a través de la confirmación de las resoluciones cargadas en el sistema. 10. Cumplir con los indicadores de gestión establecidos. | AJ20: 1 SI | AK20: 1 PUBLICADO | AL20: 1 PUBLICADO | AM20: 1 SI | AN20: 31111 | AO20: =IF(YEAR(TODAY())-YEAR(AN20)>100," ",YEAR(TODAY())-YEAR(AN20)) -> 40 | AP20: GRUPO_DE_CONTRATACIÓN | AQ20: SEBASTIAN AYALA | BF20: =BC20+BE20 -> 0 | BI20: =BF20+Q20 -> 363 | BJ20: =IF(BH20="",P20+BF20,BH20) -> 45657 | CC20: =BR20+BV20+BZ20 -> 0 | CE20: =IF(Y20=0,(W20+CC20)-CD20,IF(Y20>0,(Y20+CC20)-CD20)) -> 55908468 | CG20: =IFERROR(IF(((CE20/BI20)*(TODAY()-N20))>CE20,CE20,((CE20/BI20)*(TODAY()-N20))),"") -> 55908468 | CH20: =IF(TODAY()>BJ20,1,+(DAYS360(O20,TODAY())/DAYS360(O20,BJ20))) -> 1 | CI20: =+IF(CL20>0,DAYS360(O20,CL20)/DAYS360(O20,BJ20),CH20) -> 1 | CJ20: =IFERROR(IF(((CG20/CE20)*100)>100,100,((CG20/CE20)*100)),"") -> 100 | CK20: =IFERROR((CF20/CE20)*100,"") -> 0 | CM20: =IF(CL20>1/1/6,"LIQUIDADO",IF(BJ20=0,"",IF(BJ20>=TODAY(),"VIGENTE",IF(BJ20<TODAY(),"TERMINADO",)))) -> TERMINADO | CO20: 20243030000170-I Id: 4085637 | CP20: FEMENINO
A21: 12.16 | B21: 2024-0020 | C21: CTO | D21: CD-020-2024 | E21: 9 PRESTACIÓN DE SERVICIOS | F21: 1 PERSONA NATURAL | G21: 3 CÉDULA DE CIUDADANÍA | H21: 1015476312 | I21: JULIETH SOSA ROMERO | L21: PRESTAR SERVICIOS TÉCNICOS PARA APOYAR LA MEJORA DE PROCESOS PRESUPUESTALES, GESTIONANDO LA EN LA IMPLEMENTACIÓN DE LOS SISTEMAS DE GESTIÓN PRESUPUESTAL REALIZANDO EL DEBIDO ACOMPAÑAMIENTO PARA LA APROPIACIÓN DE LOS MISMOS EN EL MARCO DEL PROYECTO DE INVERSIÓN DE BANCA ABIERTA Y TRANSPARENTE E INHOUSE BANKING. | M21: BOGOTA | N21: 45294 | O21: 45294 | P21: 45657 | Q21: =P21-O21 -> 363 | R21: 2 INVERSIÓN | S21: CDEF-30-2024 | T21: BANCA ABIERTA Y TRANSPARENTE E INHOUSE B | U21: 46643904 | V21: IG332902005 | W21: 46643904 | X21: 3886992 | AA21: SECRETARÍA_GENERAL | AB21: =IFERROR(VLOOKUP(AA21,Listas!$A$1:$C$14,2,FALSE),"") -> FREDY CÉSPEDES VILLA | AC21: =IFERROR(VLOOKUP(AA21,Listas!$A$1:$C$14,3,FALSE),"") -> 93363483 | AD21: VICEPRESIDENCIA_FINANCIERA | AE21: COORDINADOR(A) GRUPO DE PRESUPUESTO | AF21: =IFERROR(VLOOKUP(AE21,Listas!$AD$1:$AF$66,2,FALSE),"") -> GISSET XIMENA BARRETO VILLAMIL | AG21: =IFERROR(VLOOKUP(AE21,Listas!$AD$1:$AF$65,3,FALSE),"") -> 1015408521 | AH21: 1 CONTRATACION DIRECTA | AI21: 1. Apoyar la sistematización, simplificación y optimización de procesos presupuestales que se adelantan en el marco de la modernización de las funciones financieras del Instituto y del proyecto de inversión In House Banking. 2. Apoyar en la apropiación de lineamientos para optimizar la gestión financiera y presupuestal, a partir del soporte operativo a los sistemas y bases de datos, en el marco de la implementación del proyecto de banca abierta y transparente e inhouse banking. 3. Apoyar en la gestión, validación y seguimiento de las solicitudes de índole presupuestal radicadas mediante los aplicativos de gestión adoptados por el Instituto para la generación de datos en tiempo real. 4. Apoyar en la gestión de requerimientos relacionados con las oportunidades de mejora de los aplicativos financieros del ICETEX, a través de la producción de informes, reportes y/o tableros de control. 5. Apoyar el despliegue, apropiación y estabilización e integración de aplicativos con los que cuenta el ICETEX para la gestión presupuestal. 6. Apoyar en la estructuración insumos para el seguimiento de la gestión de pagos de la entidad y la gestión de alertas tempranas que permitan la implementación de los más altos estándares y buenas prácticas en banca abierta y transparente e inhouse banking 7. Apoyar en la gestión de pagos, requeridos por los ordenadores del gasto, ejecutores y órganos de vigilancia y control, a través de la producción de informes, reportes y/o tableros de control. 8. Apoyar la administración y registros presupuestales relacionados con recursos Propios acorde a los procedimientos y lineamientos establecidos, que permitan garantizar la calidad de la información y la producción de información en tiempo real. 9. Apoyar al Grupo de Presupuesto en los procesos de administración, sistematización y validación de la información presupuestal para la generación de estadísticas de la operación. 10. Las demás obligaciones que se requieran para el cumplimiento a cabalidad del objeto contractual y que sean inherentes a la naturaleza del contrato. 11. Cumplir con los indicadores de gestión establecidos. | AJ21: 1 SI | AK21: 1 PUBLICADO | AL21: 1 PUBLICADO | AM21: 1 SI | AN21: 36018 | AO21: =IF(YEAR(TODAY())-YEAR(AN21)>100," ",YEAR(TODAY())-YEAR(AN21)) -> 27 | AP21: GRUPO_DE_CONTRATACIÓN | AQ21: SEBASTIAN AYALA | BF21: =BC21+BE21 -> 0 | BI21: =BF21+Q21 -> 363 | BJ21: =IF(BH21="",P21+BF21,BH21) -> 45657 | CC21: =BR21+BV21+BZ21 -> 0 | CE21: =IF(Y21=0,(W21+CC21)-CD21,IF(Y21>0,(Y21+CC21)-CD21)) -> 46643904 | CG21: =IFERROR(IF(((CE21/BI21)*(TODAY()-N21))>CE21,CE21,((CE21/BI21)*(TODAY()-N21))),"") -> 46643904 | CH21: =IF(TODAY()>BJ21,1,+(DAYS360(O21,TODAY())/DAYS360(O21,BJ21))) -> 1 | CI21: =+IF(CL21>0,DAYS360(O21,CL21)/DAYS360(O21,BJ21),CH21) -> 1 | CJ21: =IFERROR(IF(((CG21/CE21)*100)>100,100,((CG21/CE21)*100)),"") -> 100 | CK21: =IFERROR((CF21/CE21)*100,"") -> 0 | CM21: =IF(CL21>1/1/6,"LIQUIDADO",IF(BJ21=0,"",IF(BJ21>=TODAY(),"VIGENTE",IF(BJ21<TODAY(),"TERMINADO",)))) -> TERMINADO | CO21: 20243030000172-I Id: 4085640 | CP21: FEMENINO
A22: 12.2 | B22: 2024-0021 | C22: CTO | D22: CD-021-2024 | E22: 9 PRESTACIÓN DE SERVICIOS | F22: 1 PERSONA NATURAL | G22: 3 CÉDULA DE CIUDADANÍA | H22: 1049624779 | I22: JENNIFER VIVIANA DÍAZ CARO | L22: PRESTAR LOS SERVICIOS PROFESIONALES ESPECIALIZADOS PARA LA ESTRUCTURACIÓN, SEGUIMIENTO Y CONTROL TÉCNICO Y PRESUPUESTAL DE INICIATIVAS RELACIONADAS CON LA EJECUCIÓN DE PROYECTOS ESTRATÉGICOS Y DE INVERSIÓN A CARGO DE LA VICEPRESIDENCIA FINANCIERA, BASADOS EN LA OPTIMIZACIÓN DE PROCEDIMIENTOS PARA LA GENERACIÓN DE SOLUCIONES FINANCIERAS ACORDES A LAS NECESIDADES DE LOS GRUPOS DE INCIDENCIA PARA LA OPTIMIZACIÓN DE LA ESTRUCTURA PASIVO Y DIVERSIFICACIÓN DE LAS FUENTES DE FONDEO. | M22: BOGOTA | N22: 45294 | O22: 45295 | P22: 45657 | Q22: =P22-O22 -> 362 | R22: 2 INVERSIÓN | S22: CDEF-07-2024 | T22: OPTIMIZACIÓN DEL PASIVO Y DIVERSIFICACIÓ | U22: 167142384 | V22: IG332902004 | W22: 167142384 | X22: 13928532 | AA22: SECRETARÍA_GENERAL | AB22: =IFERROR(VLOOKUP(AA22,Listas!$A$1:$C$14,2,FALSE),"") -> FREDY CÉSPEDES VILLA | AC22: =IFERROR(VLOOKUP(AA22,Listas!$A$1:$C$14,3,FALSE),"") -> 93363483 | AD22: VICEPRESIDENCIA_FINANCIERA | AE22: VICEPRESIDENTE FINANCIERO | AF22: =IFERROR(VLOOKUP(AE22,Listas!$AD$1:$AF$66,2,FALSE),"") -> EDGAR ANTONIO GÓMEZ ÁLVAREZ | AG22: =IFERROR(VLOOKUP(AE22,Listas!$AD$1:$AF$65,3,FALSE),"") -> 2231755 | AH22: 1 CONTRATACION DIRECTA | AI22: 1. Apoyar en la coordinación de la implementación y apropiación de mecanismos y herramientas de seguimiento, control y reporte de los proyectos, planes e iniciativas contemplados en el plan estratégico del Instituto, a cargo de la dependencia según la metodología establecida por la Oficina Asesora de Planeación. 2. Apoyar en la coordinación de la estabilización, apropiación y despliegue de procesos optimizados para la administración, seguimiento y gestión de las fuentes de fondeo que permitan generar eficiencias financieras a los grupos de incidencia. 3. Articular las diferentes instancias para la implementación de iniciativas de la Vicepresidencia Financiera con el objetivo de consolidar a adopción de buenas prácticas, lineamientos y estándares que permitan fortalecer las capacidades operativas y la cultura de control, mitigación de riesgos y eficiencia administrativa. 4. Apoyar en la formulación y apropiación de indicadores que permitan mejorar la oportunidad de seguimiento y reporte relacionados con las funciones financieras del Instituto, a través de la articulación del seguimiento y control de KPI´s (key performance indicators) de la Vicepresidencia Financiera y del Instituto. 5. Estructurar documentos técnicos, reglamentación o actos administrativos requeridos para la implementación de lineamientos, estándares y buenas prácticas en el marco del despliegue de proyectos estratégicos y de inversión a cargo de la Vicepresidencia Financiera. 6. Apoyar en la estructuración de los insumos técnicos para el análisis, gestión y consecución de aliados estratégicos que apalanquen el proyecto de transformación del Instituto, y especialmente lo relacionado con la diversificación de fuentes de fondeo en la búsqueda permanente de esquemas de financiación que permitan optimizar la estructura financiera del ICETEX. 7. Apoyar en la coordinación del despliegue de iniciativas, planes, proyectos, iniciativas y estrategias asignadas, y que se encaminen al cumplimiento de metas y despliegue de servicios financieros de calidad, eficientes e innovadores que fortalezca la apropiación de los principios de banca abierta y transparente adoptado por la entidad 8. Gestionar acciones que permitan la simplificación, estandarización y optimización de procesos asociados al sistema de calidad y que permitan modernización de las funciones financieras del ICETEX. 9. Estructurar los estudios, análisis del sector económico, matriz de riesgos y demás insumos requeridos por la normatividad vigente, que permita adelantar los procesos en el marco de la implementación de los proyectos de inversión a cargo de la Vicepresidencia Financiera. 10. Articular con instancias internas y externas el despliegue e implementación de los proyectos de inversión de la Vicepresidencia Financiera, a partir de un esquema por áreas de gestión en el marco de implementación de los principios de banca abierta y transparente. 11. Cumplir con los indicadores de gestión establecidos. 12. Las demás obligaciones que se requieran para el cumplimiento a cabalidad del objeto contractual y que sean inherentes a la naturaleza del contrato. | AJ22: 1 SI | AK22: 1 PUBLICADO | AL22: 1 PUBLICADO | AM22: 1 SI | AN22: 33290 | AO22: =IF(YEAR(TODAY())-YEAR(AN22)>100," ",YEAR(TODAY())-YEAR(AN22)) -> 34 | AP22: GRUPO_DE_CONTRATACIÓN | AQ22: SEBASTIAN AYALA | BF22: =BC22+BE22 -> 0 | BI22: =BF22+Q22 -> 362 | BJ22: =IF(BH22="",P22+BF22,BH22) -> 45657 | CC22: =BR22+BV22+BZ22 -> 0 | CE22: =IF(Y22=0,(W22+CC22)-CD22,IF(Y22>0,(Y22+CC22)-CD22)) -> 167142384 | CG22: =IFERROR(IF(((CE22/BI22)*(TODAY()-N22))>CE22,CE22,((CE22/BI22)*(TODAY()-N22))),"") -> 167142384 | CH22: =IF(TODAY()>BJ22,1,+(DAYS360(O22,TODAY())/DAYS360(O22,BJ22))) -> 1 | CI22: =+IF(CL22>0,DAYS360(O22,CL22)/DAYS360(O22,BJ22),CH22) -> 1 | CJ22: =IFERROR(IF(((CG22/CE22)*100)>100,100,((CG22/CE22)*100)),"") -> 100 | CK22: =IFERROR((CF22/CE22)*100,"") -> 0 | CM22: =IF(CL22>1/1/6,"LIQUIDADO",IF(BJ22=0,"",IF(BJ22>=TODAY(),"VIGENTE",IF(BJ22<TODAY(),"TERMINADO",)))) -> TERMINADO | CO22: 20243030000202-I Id: 4085701 | CP22: FEMENINO
